<?xml version="1.0" ?>
<robot name="zeta" xmlns:xacro="http://www.ros.org/wiki/xacro">

<xacro:include filename="$(find zeta_description)/urdf/materials.xacro" />
<xacro:include filename="$(find zeta_description)/urdf/zeta.trans" />

<xacro:include filename="$(find zeta_description)/gazebo/zeta_materials.gazebo" />
<xacro:include filename="$(find zeta_description)/gazebo/zeta_physics.gazebo" />
<xacro:include filename="$(find zeta_description)/gazebo/zeta_plugins.gazebo" />

<link name="base_link">
  <inertial>
    <origin rpy="0 0 0" xyz="-0.14461409332930716 0.0883518788335936 0.2064875843501072"/>
    <mass value="0.26109888559714134"/>
    <inertia ixx="0.000188" ixy="0.0" ixz="-0.0" iyy="0.003858" iyz="-0.0" izz="0.003995"/>
  </inertial>
  <visual>
    <origin rpy="0 0 0" xyz="0 0 0"/>
    <geometry>
      <mesh filename="package://zeta_description/meshes/base_link.stl" scale="0.001 0.001 0.001"/>
    </geometry>
    <material name="silver"/>
  </visual>
  <collision>
    <origin rpy="0 0 0" xyz="0 0 0"/>
    <geometry>
      <mesh filename="package://zeta_description/meshes/base_link.stl" scale="0.001 0.001 0.001"/>
    </geometry>
  </collision>
</link>

<link name="BL_foot_1">
  <inertial>
    <origin rpy="0 0 0" xyz="0.05644955069451385 -0.01619715461445445 -0.056449524198164465"/>
    <mass value="0.050254366168808934"/>
    <inertia ixx="4e-05" ixy="0.0" ixz="3.4e-05" iyy="7.1e-05" iyz="-0.0" izz="4e-05"/>
  </inertial>
  <visual>
    <origin rpy="0 0 0" xyz="0.333552 -0.203521 -0.100725"/>
    <geometry>
      <mesh filename="package://zeta_description/meshes/BL_foot_1.stl" scale="0.001 0.001 0.001"/>
    </geometry>
    <material name="silver"/>
  </visual>
  <collision>
    <origin rpy="0 0 0" xyz="0.333552 -0.203521 -0.100725"/>
    <geometry>
      <mesh filename="package://zeta_description/meshes/BL_foot_1.stl" scale="0.001 0.001 0.001"/>
    </geometry>
  </collision>
</link>

<link name="BL_motor_block_1">
  <inertial>
    <origin rpy="0 0 0" xyz="-0.027223152863659228 -0.014672109847305964 -0.02722359848924935"/>
    <mass value="0.08833659369300421"/>
    <inertia ixx="4.7e-05" ixy="-0.0" ixz="-3.2e-05" iyy="8e-05" iyz="0.0" izz="4.7e-05"/>
  </inertial>
  <visual>
    <origin rpy="0 0 0" xyz="0.279105 -0.203521 -0.155172"/>
    <geometry>
      <mesh filename="package://zeta_description/meshes/BL_motor_block_1.stl" scale="0.001 0.001 0.001"/>
    </geometry>
    <material name="silver"/>
  </visual>
  <collision>
    <origin rpy="0 0 0" xyz="0.279105 -0.203521 -0.155172"/>
    <geometry>
      <mesh filename="package://zeta_description/meshes/BL_motor_block_1.stl" scale="0.001 0.001 0.001"/>
    </geometry>
  </collision>
</link>

<link name="BL_top_1">
  <inertial>
    <origin rpy="0 0 0" xyz="0.016013586630673704 0.047570667286835455 -0.011363799013344889"/>
    <mass value="0.026371988478748627"/>
    <inertia ixx="2.3e-05" ixy="-0.0" ixz="0.0" iyy="1.1e-05" iyz="4e-06" izz="1.8e-05"/>
  </inertial>
  <visual>
    <origin rpy="0 0 0" xyz="0.295505 -0.128052 -0.206491"/>
    <geometry>
      <mesh filename="package://zeta_description/meshes/BL_top_1.stl" scale="0.001 0.001 0.001"/>
    </geometry>
    <material name="silver"/>
  </visual>
  <collision>
    <origin rpy="0 0 0" xyz="0.295505 -0.128052 -0.206491"/>
    <geometry>
      <mesh filename="package://zeta_description/meshes/BL_top_1.stl" scale="0.001 0.001 0.001"/>
    </geometry>
  </collision>
</link>

<link name="BR_foot_1">
  <inertial>
    <origin rpy="0 0 0" xyz="0.0564495506979143 0.016196912277002512 -0.05644952420106039"/>
    <mass value="0.050254366173962006"/>
    <inertia ixx="4e-05" ixy="-0.0" ixz="3.4e-05" iyy="7.1e-05" iyz="0.0" izz="4e-05"/>
  </inertial>
  <visual>
    <origin rpy="0 0 0" xyz="0.333552 0.026817 -0.100725"/>
    <geometry>
      <mesh filename="package://zeta_description/meshes/BR_foot_1.stl" scale="0.001 0.001 0.001"/>
    </geometry>
    <material name="silver"/>
  </visual>
  <collision>
    <origin rpy="0 0 0" xyz="0.333552 0.026817 -0.100725"/>
    <geometry>
      <mesh filename="package://zeta_description/meshes/BR_foot_1.stl" scale="0.001 0.001 0.001"/>
    </geometry>
  </collision>
</link>

<link name="BR_motor_block_1">
  <inertial>
    <origin rpy="0 0 0" xyz="-0.027223152862709155 0.014671867515031146 -0.02722359848963765"/>
    <mass value="0.08833659369327077"/>
    <inertia ixx="4.7e-05" ixy="-0.0" ixz="-3.2e-05" iyy="8e-05" iyz="0.0" izz="4.7e-05"/>
  </inertial>
  <visual>
    <origin rpy="0 0 0" xyz="0.279105 0.026817 -0.155172"/>
    <geometry>
      <mesh filename="package://zeta_description/meshes/BR_motor_block_1.stl" scale="0.001 0.001 0.001"/>
    </geometry>
    <material name="silver"/>
  </visual>
  <collision>
    <origin rpy="0 0 0" xyz="0.279105 0.026817 -0.155172"/>
    <geometry>
      <mesh filename="package://zeta_description/meshes/BR_motor_block_1.stl" scale="0.001 0.001 0.001"/>
    </geometry>
  </collision>
</link>

<link name="BR_top_1">
  <inertial>
    <origin rpy="0 0 0" xyz="0.016013586630497123 -0.04757090961961194 -0.011363799013237114"/>
    <mass value="0.026371988478739887"/>
    <inertia ixx="2.3e-05" ixy="0.0" ixz="0.0" iyy="1.1e-05" iyz="-4e-06" izz="1.8e-05"/>
  </inertial>
  <visual>
    <origin rpy="0 0 0" xyz="0.295505 -0.048652 -0.206491"/>
    <geometry>
      <mesh filename="package://zeta_description/meshes/BR_top_1.stl" scale="0.001 0.001 0.001"/>
    </geometry>
    <material name="silver"/>
  </visual>
  <collision>
    <origin rpy="0 0 0" xyz="0.295505 -0.048652 -0.206491"/>
    <geometry>
      <mesh filename="package://zeta_description/meshes/BR_top_1.stl" scale="0.001 0.001 0.001"/>
    </geometry>
  </collision>
</link>

<link name="FR_top_1">
  <inertial>
    <origin rpy="0 0 0" xyz="0.016013586630579342 -0.04757090961960731 -0.011363799013341308"/>
    <mass value="0.026371988478748786"/>
    <inertia ixx="2.3e-05" ixy="0.0" ixz="0.0" iyy="1.1e-05" iyz="-4e-06" izz="1.8e-05"/>
  </inertial>
  <visual>
    <origin rpy="0 0 0" xyz="0.024505 -0.048652 -0.206491"/>
    <geometry>
      <mesh filename="package://zeta_description/meshes/FR_top_1.stl" scale="0.001 0.001 0.001"/>
    </geometry>
    <material name="silver"/>
  </visual>
  <collision>
    <origin rpy="0 0 0" xyz="0.024505 -0.048652 -0.206491"/>
    <geometry>
      <mesh filename="package://zeta_description/meshes/FR_top_1.stl" scale="0.001 0.001 0.001"/>
    </geometry>
  </collision>
</link>

<link name="FL_foot_1">
  <inertial>
    <origin rpy="0 0 0" xyz="0.05644955069451409 -0.016197154614456588 -0.056449524198166345"/>
    <mass value="0.0502543661688089"/>
    <inertia ixx="4e-05" ixy="0.0" ixz="3.4e-05" iyy="7.1e-05" iyz="-0.0" izz="4e-05"/>
  </inertial>
  <visual>
    <origin rpy="0 0 0" xyz="0.062552 -0.203521 -0.100725"/>
    <geometry>
      <mesh filename="package://zeta_description/meshes/FL_foot_1.stl" scale="0.001 0.001 0.001"/>
    </geometry>
    <material name="silver"/>
  </visual>
  <collision>
    <origin rpy="0 0 0" xyz="0.062552 -0.203521 -0.100725"/>
    <geometry>
      <mesh filename="package://zeta_description/meshes/FL_foot_1.stl" scale="0.001 0.001 0.001"/>
    </geometry>
  </collision>
</link>

<link name="FL_motor_block_1">
  <inertial>
    <origin rpy="0 0 0" xyz="-0.02718553583877841 -0.014671926830458815 -0.027187005197919556"/>
    <mass value="0.08843072327026845"/>
    <inertia ixx="4.7e-05" ixy="-0.0" ixz="-3.2e-05" iyy="8.1e-05" iyz="-0.0" izz="4.7e-05"/>
  </inertial>
  <visual>
    <origin rpy="0 0 0" xyz="0.008105 -0.203521 -0.155172"/>
    <geometry>
      <mesh filename="package://zeta_description/meshes/FL_motor_block_1.stl" scale="0.001 0.001 0.001"/>
    </geometry>
    <material name="silver"/>
  </visual>
  <collision>
    <origin rpy="0 0 0" xyz="0.008105 -0.203521 -0.155172"/>
    <geometry>
      <mesh filename="package://zeta_description/meshes/FL_motor_block_1.stl" scale="0.001 0.001 0.001"/>
    </geometry>
  </collision>
</link>

<link name="FL_top_1">
  <inertial>
    <origin rpy="0 0 0" xyz="0.0160135866305811 0.04757066728683562 -0.011363799013343834"/>
    <mass value="0.02637198847874842"/>
    <inertia ixx="2.3e-05" ixy="-0.0" ixz="0.0" iyy="1.1e-05" iyz="4e-06" izz="1.8e-05"/>
  </inertial>
  <visual>
    <origin rpy="0 0 0" xyz="0.024505 -0.128052 -0.206491"/>
    <geometry>
      <mesh filename="package://zeta_description/meshes/FL_top_1.stl" scale="0.001 0.001 0.001"/>
    </geometry>
    <material name="silver"/>
  </visual>
  <collision>
    <origin rpy="0 0 0" xyz="0.024505 -0.128052 -0.206491"/>
    <geometry>
      <mesh filename="package://zeta_description/meshes/FL_top_1.stl" scale="0.001 0.001 0.001"/>
    </geometry>
  </collision>
</link>

<link name="R_Pipe_1">
  <inertial>
    <origin rpy="0 0 0" xyz="0.1149254583128192 -0.00019701609423813937 -3.9498945669791397e-08"/>
    <mass value="0.06072232848588734"/>
    <inertia ixx="5e-06" ixy="0.0" ixz="0.0" iyy="0.00027" iyz="-0.0" izz="0.00027"/>
  </inertial>
  <visual>
    <origin rpy="0 0 0" xyz="0.260605 -0.067967 -0.206491"/>
    <geometry>
      <mesh filename="package://zeta_description/meshes/R_Pipe_1.stl" scale="0.001 0.001 0.001"/>
    </geometry>
    <material name="silver"/>
  </visual>
  <collision>
    <origin rpy="0 0 0" xyz="0.260605 -0.067967 -0.206491"/>
    <geometry>
      <mesh filename="package://zeta_description/meshes/R_Pipe_1.stl" scale="0.001 0.001 0.001"/>
    </geometry>
  </collision>
</link>

<link name="L_Pipe_1">
  <inertial>
    <origin rpy="0 0 0" xyz="0.11492545831281933 0.00019677376152678339 -3.949894572530255e-08"/>
    <mass value="0.06072232848588743"/>
    <inertia ixx="5e-06" ixy="0.0" ixz="0.0" iyy="0.00027" iyz="-0.0" izz="0.00027"/>
  </inertial>
  <visual>
    <origin rpy="0 0 0" xyz="0.260605 -0.108737 -0.206491"/>
    <geometry>
      <mesh filename="package://zeta_description/meshes/L_Pipe_1.stl" scale="0.001 0.001 0.001"/>
    </geometry>
    <material name="silver"/>
  </visual>
  <collision>
    <origin rpy="0 0 0" xyz="0.260605 -0.108737 -0.206491"/>
    <geometry>
      <mesh filename="package://zeta_description/meshes/L_Pipe_1.stl" scale="0.001 0.001 0.001"/>
    </geometry>
  </collision>
</link>

<link name="FR_foot_1">
  <inertial>
    <origin rpy="0 0 0" xyz="0.05644955069791327 0.01619691227700047 -0.05644952420106501"/>
    <mass value="0.05025436617396211"/>
    <inertia ixx="4e-05" ixy="-0.0" ixz="3.4e-05" iyy="7.1e-05" iyz="0.0" izz="4e-05"/>
  </inertial>
  <visual>
    <origin rpy="0 0 0" xyz="0.062552 0.026817 -0.100725"/>
    <geometry>
      <mesh filename="package://zeta_description/meshes/FR_foot_1.stl" scale="0.001 0.001 0.001"/>
    </geometry>
    <material name="silver"/>
  </visual>
  <collision>
    <origin rpy="0 0 0" xyz="0.062552 0.026817 -0.100725"/>
    <geometry>
      <mesh filename="package://zeta_description/meshes/FR_foot_1.stl" scale="0.001 0.001 0.001"/>
    </geometry>
  </collision>
</link>

<link name="FR_motor_block_1">
  <inertial>
    <origin rpy="0 0 0" xyz="-0.027185535838667285 0.014671684498179257 -0.0271870051983098"/>
    <mass value="0.0884307232705417"/>
    <inertia ixx="4.7e-05" ixy="0.0" ixz="-3.2e-05" iyy="8.1e-05" iyz="0.0" izz="4.7e-05"/>
  </inertial>
  <visual>
    <origin rpy="0 0 0" xyz="0.008105 0.026817 -0.155172"/>
    <geometry>
      <mesh filename="package://zeta_description/meshes/FR_motor_block_1.stl" scale="0.001 0.001 0.001"/>
    </geometry>
    <material name="silver"/>
  </visual>
  <collision>
    <origin rpy="0 0 0" xyz="0.008105 0.026817 -0.155172"/>
    <geometry>
      <mesh filename="package://zeta_description/meshes/FR_motor_block_1.stl" scale="0.001 0.001 0.001"/>
    </geometry>
  </collision>
</link>

<joint name="Rev46" type="continuous">
  <origin rpy="0 0 0" xyz="-0.054447 0.0 -0.054447"/>
  <parent link="BL_motor_block_1"/>
  <child link="BL_foot_1"/>
  <axis xyz="0.0 1.0 -0.0"/>
</joint>

<joint name="Rev47" type="continuous">
  <origin rpy="0 0 0" xyz="0.0164 0.075469 -0.051319"/>
  <parent link="BL_top_1"/>
  <child link="BL_motor_block_1"/>
  <axis xyz="0.0 -1.0 0.0"/>
</joint>

<joint name="Rev48" type="continuous">
  <origin rpy="0 0 0" xyz="-0.295505 0.128052 0.206491"/>
  <parent link="base_link"/>
  <child link="BL_top_1"/>
  <axis xyz="1.0 -0.0 -0.0"/>
</joint>

<joint name="Rev49" type="continuous">
  <origin rpy="0 0 0" xyz="-0.054447 0.0 -0.054447"/>
  <parent link="BR_motor_block_1"/>
  <child link="BR_foot_1"/>
  <axis xyz="-0.0 -1.0 0.0"/>
</joint>

<joint name="Rev50" type="continuous">
  <origin rpy="0 0 0" xyz="0.0164 -0.075469 -0.051319"/>
  <parent link="BR_top_1"/>
  <child link="BR_motor_block_1"/>
  <axis xyz="-0.0 -1.0 0.0"/>
</joint>

<joint name="Rev51" type="continuous">
  <origin rpy="0 0 0" xyz="-0.295505 0.048652 0.206491"/>
  <parent link="base_link"/>
  <child link="BR_top_1"/>
  <axis xyz="-1.0 0.0 0.0"/>
</joint>

<joint name="Rev54" type="continuous">
  <origin rpy="0 0 0" xyz="-0.024505 0.048652 0.206491"/>
  <parent link="base_link"/>
  <child link="FR_top_1"/>
  <axis xyz="-1.0 0.0 0.0"/>
</joint>

<joint name="Rev55" type="continuous">
  <origin rpy="0 0 0" xyz="-0.054447 0.0 -0.054447"/>
  <parent link="FL_motor_block_1"/>
  <child link="FL_foot_1"/>
  <axis xyz="0.0 -1.0 -0.0"/>
</joint>

<joint name="Rev56" type="continuous">
  <origin rpy="0 0 0" xyz="0.0164 0.075469 -0.051319"/>
  <parent link="FL_top_1"/>
  <child link="FL_motor_block_1"/>
  <axis xyz="0.0 -1.0 0.0"/>
</joint>

<joint name="Rev57" type="continuous">
  <origin rpy="0 0 0" xyz="-0.024505 0.128052 0.206491"/>
  <parent link="base_link"/>
  <child link="FL_top_1"/>
  <axis xyz="1.0 -0.0 -0.0"/>
</joint>

<joint name="Rigid58" type="fixed">
  <origin rpy="0 0 0" xyz="-0.260605 0.067967 0.206491"/>
  <parent link="base_link"/>
  <child link="R_Pipe_1"/>
</joint>

<joint name="Rigid59" type="fixed">
  <origin rpy="0 0 0" xyz="-0.260605 0.108737 0.206491"/>
  <parent link="base_link"/>
  <child link="L_Pipe_1"/>
</joint>

<joint name="Rev61" type="continuous">
  <origin rpy="0 0 0" xyz="-0.054447 0.0 -0.054447"/>
  <parent link="FR_motor_block_1"/>
  <child link="FR_foot_1"/>
  <axis xyz="-0.0 -1.0 0.0"/>
</joint>

<joint name="Rev62" type="continuous">
  <origin rpy="0 0 0" xyz="0.0164 -0.075469 -0.051319"/>
  <parent link="FR_top_1"/>
  <child link="FR_motor_block_1"/>
  <axis xyz="-0.0 -1.0 0.0"/>
</joint>

</robot>
