<?xml version="1.0" ?>
<robot name="zeta_urdf" xmlns:xacro="http://www.ros.org/wiki/xacro">


<material name="silver_default">
  <color rgba="0.700 0.700 0.700 1.000"/>
</material>
<material name="opaque252525">
  <color rgba="0.09803921568627451 0.09803921568627451 0.09803921568627451 1.0"/>
</material>
<material name="opaque246246243">
  <color rgba="0.9647058823529412 0.9647058823529412 0.9529411764705882 1.0"/>
</material>


<xacro:include filename="$(find zeta_urdf_description)/urdf/zeta_urdf.trans" />
<xacro:include filename="$(find zeta_urdf_description)/urdf/zeta_urdf.gazebo" />

<link name="dummy">
   </link>

<link name="base_link">
  <inertial>
    <origin xyz="0.5865154177311522 -0.47938007450948616 0.24225184206557204" rpy="0 0 0"/>
    <mass value="0.13102657430451126"/>
    <inertia ixx="0.0001" ixy="0.000"  ixz="0.000"  
         iyy="0.0001" iyz="0.000"
         izz="0.0001"
/>
  </inertial>
  <visual>
    <origin xyz="0 0 0" rpy="0 0 0"/>
    <geometry>
      <mesh filename="package://zeta_urdf_description/meshes/base_link.stl" scale="0.001 0.001 0.001"/>
    </geometry>
    <material name="opaque252525"/>
  </visual>
  <collision>
    <origin xyz="0 0 0" rpy="0 0 0"/>
    <geometry>
      <mesh filename="package://zeta_urdf_description/meshes/base_link.stl" scale="0.001 0.001 0.001"/>
    </geometry>
  </collision>
</link>

  <joint name="dummy_joint" type="fixed">
     <parent link="dummy"/>
     <child link="base_link"/>
   </joint>

<link name="FL_Foot_1">
  <inertial>
    <origin xyz="0.05644893372034021 -0.015447107956216288 -0.056449484510780606" rpy="0 0 0"/>
    <mass value="0.050254366164942214"/>
    <inertia ixx="0.0001" ixy="0.000"  ixz="0.000"  
         iyy="0.0001" iyz="0.000"
         izz="0.0001"
/>
  </inertial>
  <visual>
    <origin xyz="-0.667176 0.364961 -0.136492" rpy="0 0 0"/>
    <geometry>
      <mesh filename="package://zeta_urdf_description/meshes/FL_Foot_1.stl" scale="0.001 0.001 0.001"/>
    </geometry>
    <material name="opaque252525"/>
  </visual>
  <collision>
    <origin xyz="-0.667176 0.364961 -0.136492" rpy="0 0 0"/>
    <geometry>
      <mesh filename="package://zeta_urdf_description/meshes/FL_Foot_1.stl" scale="0.001 0.001 0.001"/>
    </geometry>
  </collision>
</link>

<link name="FL_Dual_Motor_Mount_1">
  <inertial>
    <origin xyz="-0.01785632295995343 -1.2666584658926894e-07 -0.01785880452042632" rpy="0 0 0"/>
    <mass value="0.023417593270727483"/>
    <inertia ixx="0.0001" ixy="0.000"  ixz="0.000"  
         iyy="0.0001" iyz="0.000"
         izz="0.0001"
/>
  </inertial>
  <visual>
    <origin xyz="-0.71243 0.379461 -0.181747" rpy="0 0 0"/>
    <geometry>
      <mesh filename="package://zeta_urdf_description/meshes/FL_Dual_Motor_Mount_1.stl" scale="0.001 0.001 0.001"/>
    </geometry>
    <material name="opaque252525"/>
  </visual>
  <collision>
    <origin xyz="-0.71243 0.379461 -0.181747" rpy="0 0 0"/>
    <geometry>
      <mesh filename="package://zeta_urdf_description/meshes/FL_Dual_Motor_Mount_1.stl" scale="0.001 0.001 0.001"/>
    </geometry>
  </collision>
</link>

<link name="FL_Top_Bracket_1">
  <inertial>
    <origin xyz="0.015262969658813352 0.04757071394376694 -0.011363759328014672" rpy="0 0 0"/>
    <mass value="0.026371988478740775"/>
    <inertia ixx="0.0001" ixy="0.000"  ixz="0.000"  
         iyy="0.0001" iyz="0.000"
         izz="0.0001"
/>
  </inertial>
  <visual>
    <origin xyz="-0.705973 0.43968 -0.242258" rpy="0 0 0"/>
    <geometry>
      <mesh filename="package://zeta_urdf_description/meshes/FL_Top_Bracket_1.stl" scale="0.001 0.001 0.001"/>
    </geometry>
    <material name="opaque252525"/>
  </visual>
  <collision>
    <origin xyz="-0.705973 0.43968 -0.242258" rpy="0 0 0"/>
    <geometry>
      <mesh filename="package://zeta_urdf_description/meshes/FL_Top_Bracket_1.stl" scale="0.001 0.001 0.001"/>
    </geometry>
  </collision>
</link>

<link name="FR_Top_Bracket_1">
  <inertial>
    <origin xyz="0.015262969658811354 -0.04757086296280377 -0.011363759328016143" rpy="0 0 0"/>
    <mass value="0.02637198847874129"/>
    <inertia ixx="0.0001" ixy="0.000"  ixz="0.000"  
         iyy="0.0001" iyz="0.000"
         izz="0.0001"
/>
  </inertial>
  <visual>
    <origin xyz="-0.705973 0.51908 -0.242258" rpy="0 0 0"/>
    <geometry>
      <mesh filename="package://zeta_urdf_description/meshes/FR_Top_Bracket_1.stl" scale="0.001 0.001 0.001"/>
    </geometry>
    <material name="opaque252525"/>
  </visual>
  <collision>
    <origin xyz="-0.705973 0.51908 -0.242258" rpy="0 0 0"/>
    <geometry>
      <mesh filename="package://zeta_urdf_description/meshes/FR_Top_Bracket_1.stl" scale="0.001 0.001 0.001"/>
    </geometry>
  </collision>
</link>

<link name="FR_3_Motor_1">
  <inertial>
    <origin xyz="0.00023268298076450922 0.00388108799207032 -4.069288939978488e-07" rpy="0 0 0"/>
    <mass value="0.09250068837166636"/>
    <inertia ixx="0.0001" ixy="0.000"  ixz="0.000"  
         iyy="0.0001" iyz="0.000"
         izz="0.0001"
/>
  </inertial>
  <visual>
    <origin xyz="-0.720473 0.50958 -0.242258" rpy="0 0 0"/>
    <geometry>
      <mesh filename="package://zeta_urdf_description/meshes/FR_3_Motor_1.stl" scale="0.001 0.001 0.001"/>
    </geometry>
    <material name="opaque252525"/>
  </visual>
  <collision>
    <origin xyz="-0.720473 0.50958 -0.242258" rpy="0 0 0"/>
    <geometry>
      <mesh filename="package://zeta_urdf_description/meshes/FR_3_Motor_1.stl" scale="0.001 0.001 0.001"/>
    </geometry>
  </collision>
</link>

<link name="Pipe_R_1">
  <inertial>
    <origin xyz="0.1149248413410463 -0.0001969694373666897 1.862640597316556e-10" rpy="0 0 0"/>
    <mass value="0.060722328485887364"/>
    <inertia ixx="0.0001" ixy="0.000"  ixz="0.000"  
         iyy="0.0001" iyz="0.000"
         izz="0.0001"
/>
  </inertial>
  <visual>
    <origin xyz="-0.469873 0.499765 -0.242258" rpy="0 0 0"/>
    <geometry>
      <mesh filename="package://zeta_urdf_description/meshes/Pipe_R_1.stl" scale="0.001 0.001 0.001"/>
    </geometry>
    <material name="opaque246246243"/>
  </visual>
  <collision>
    <origin xyz="-0.469873 0.499765 -0.242258" rpy="0 0 0"/>
    <geometry>
      <mesh filename="package://zeta_urdf_description/meshes/Pipe_R_1.stl" scale="0.001 0.001 0.001"/>
    </geometry>
  </collision>
</link>

<link name="Pipe_L_1">
  <inertial>
    <origin xyz="0.11492484134104641 0.0001968204183980804 1.8626425402068492e-10" rpy="0 0 0"/>
    <mass value="0.06072232848588741"/>
    <inertia ixx="0.0001" ixy="0.000"  ixz="0.000"  
         iyy="0.0001" iyz="0.000"
         izz="0.0001"
/>
  </inertial>
  <visual>
    <origin xyz="-0.469873 0.458995 -0.242258" rpy="0 0 0"/>
    <geometry>
      <mesh filename="package://zeta_urdf_description/meshes/Pipe_L_1.stl" scale="0.001 0.001 0.001"/>
    </geometry>
    <material name="opaque246246243"/>
  </visual>
  <collision>
    <origin xyz="-0.469873 0.458995 -0.242258" rpy="0 0 0"/>
    <geometry>
      <mesh filename="package://zeta_urdf_description/meshes/Pipe_L_1.stl" scale="0.001 0.001 0.001"/>
    </geometry>
  </collision>
</link>

<link name="BR_3_Motor_1">
  <inertial>
    <origin xyz="0.00023268298107181895 0.0038810879920733177 -4.0692889261007004e-07" rpy="0 0 0"/>
    <mass value="0.09250068837166658"/>
    <inertia ixx="0.0001" ixy="0.000"  ixz="0.000"  
         iyy="0.0001" iyz="0.000"
         izz="0.0001"
/>
  </inertial>
  <visual>
    <origin xyz="-0.449473 0.50958 -0.242258" rpy="0 0 0"/>
    <geometry>
      <mesh filename="package://zeta_urdf_description/meshes/BR_3_Motor_1.stl" scale="0.001 0.001 0.001"/>
    </geometry>
    <material name="opaque252525"/>
  </visual>
  <collision>
    <origin xyz="-0.449473 0.50958 -0.242258" rpy="0 0 0"/>
    <geometry>
      <mesh filename="package://zeta_urdf_description/meshes/BR_3_Motor_1.stl" scale="0.001 0.001 0.001"/>
    </geometry>
  </collision>
</link>

<link name="BL_3_Motor_1">
  <inertial>
    <origin xyz="0.00023268298107342877 -0.0038812370107781935 -4.0692889305415925e-07" rpy="0 0 0"/>
    <mass value="0.0925006883716665"/>
    <inertia ixx="0.0001" ixy="0.000"  ixz="0.000"  
         iyy="0.0001" iyz="0.000"
         izz="0.0001"
/>
  </inertial>
  <visual>
    <origin xyz="-0.449473 0.44918 -0.242258" rpy="0 0 0"/>
    <geometry>
      <mesh filename="package://zeta_urdf_description/meshes/BL_3_Motor_1.stl" scale="0.001 0.001 0.001"/>
    </geometry>
    <material name="opaque252525"/>
  </visual>
  <collision>
    <origin xyz="-0.449473 0.44918 -0.242258" rpy="0 0 0"/>
    <geometry>
      <mesh filename="package://zeta_urdf_description/meshes/BL_3_Motor_1.stl" scale="0.001 0.001 0.001"/>
    </geometry>
  </collision>
</link>

<link name="BR_Top_Bracket_1">
  <inertial>
    <origin xyz="0.015262969658733805 -0.047570862962798444 -0.011363759328014672" rpy="0 0 0"/>
    <mass value="0.026371988478740113"/>
    <inertia ixx="0.0001" ixy="0.000"  ixz="0.000"  
         iyy="0.0001" iyz="0.000"
         izz="0.0001"
/>
  </inertial>
  <visual>
    <origin xyz="-0.434973 0.51908 -0.242258" rpy="0 0 0"/>
    <geometry>
      <mesh filename="package://zeta_urdf_description/meshes/BR_Top_Bracket_1.stl" scale="0.001 0.001 0.001"/>
    </geometry>
    <material name="opaque252525"/>
  </visual>
  <collision>
    <origin xyz="-0.434973 0.51908 -0.242258" rpy="0 0 0"/>
    <geometry>
      <mesh filename="package://zeta_urdf_description/meshes/BR_Top_Bracket_1.stl" scale="0.001 0.001 0.001"/>
    </geometry>
  </collision>
</link>

<link name="BL_Dual_Motor_Mount_1">
  <inertial>
    <origin xyz="-0.018030769834741278 -1.2666584398024483e-07 -0.01803155880432636" rpy="0 0 0"/>
    <mass value="0.02330043804692393"/>
    <inertia ixx="0.0001" ixy="0.000"  ixz="0.000"  
         iyy="0.0001" iyz="0.000"
         izz="0.0001"
/>
  </inertial>
  <visual>
    <origin xyz="-0.44143 0.379461 -0.181747" rpy="0 0 0"/>
    <geometry>
      <mesh filename="package://zeta_urdf_description/meshes/BL_Dual_Motor_Mount_1.stl" scale="0.001 0.001 0.001"/>
    </geometry>
    <material name="opaque252525"/>
  </visual>
  <collision>
    <origin xyz="-0.44143 0.379461 -0.181747" rpy="0 0 0"/>
    <geometry>
      <mesh filename="package://zeta_urdf_description/meshes/BL_Dual_Motor_Mount_1.stl" scale="0.001 0.001 0.001"/>
    </geometry>
  </collision>
</link>

<link name="BL_Top_Bracket_1">
  <inertial>
    <origin xyz="0.015262969658734526 0.047570713943769716 -0.01136375932801384" rpy="0 0 0"/>
    <mass value="0.02637198847874093"/>
    <inertia ixx="0.0001" ixy="0.000"  ixz="0.000"  
         iyy="0.0001" iyz="0.000"
         izz="0.0001"
/>
  </inertial>
  <visual>
    <origin xyz="-0.434973 0.43968 -0.242258" rpy="0 0 0"/>
    <geometry>
      <mesh filename="package://zeta_urdf_description/meshes/BL_Top_Bracket_1.stl" scale="0.001 0.001 0.001"/>
    </geometry>
    <material name="opaque252525"/>
  </visual>
  <collision>
    <origin xyz="-0.434973 0.43968 -0.242258" rpy="0 0 0"/>
    <geometry>
      <mesh filename="package://zeta_urdf_description/meshes/BL_Top_Bracket_1.stl" scale="0.001 0.001 0.001"/>
    </geometry>
  </collision>
</link>

<link name="FL_2_Motor_1">
  <inertial>
    <origin xyz="-0.009461781630211052 -0.015482968305636502 -0.009462146346697065" rpy="0 0 0"/>
    <mass value="0.09250068837133453"/>
    <inertia ixx="0.0001" ixy="0.000"  ixz="0.000"  
         iyy="0.0001" iyz="0.000"
         izz="0.0001"
/>
  </inertial>
  <visual>
    <origin xyz="-0.721623 0.364211 -0.190939" rpy="0 0 0"/>
    <geometry>
      <mesh filename="package://zeta_urdf_description/meshes/FL_2_Motor_1.stl" scale="0.001 0.001 0.001"/>
    </geometry>
    <material name="opaque252525"/>
  </visual>
  <collision>
    <origin xyz="-0.721623 0.364211 -0.190939" rpy="0 0 0"/>
    <geometry>
      <mesh filename="package://zeta_urdf_description/meshes/FL_2_Motor_1.stl" scale="0.001 0.001 0.001"/>
    </geometry>
  </collision>
</link>

<link name="FL_1_Motor_1">
  <inertial>
    <origin xyz="0.0027442419607356383 -0.00023296830563640514 0.00274502873903551" rpy="0 0 0"/>
    <mass value="0.09250068837133453"/>
    <inertia ixx="0.0001" ixy="0.000"  ixz="0.000"  
         iyy="0.0001" iyz="0.000"
         izz="0.0001"
/>
  </inertial>
  <visual>
    <origin xyz="-0.673893 0.379461 -0.143209" rpy="0 0 0"/>
    <geometry>
      <mesh filename="package://zeta_urdf_description/meshes/FL_1_Motor_1.stl" scale="0.001 0.001 0.001"/>
    </geometry>
    <material name="opaque252525"/>
  </visual>
  <collision>
    <origin xyz="-0.673893 0.379461 -0.143209" rpy="0 0 0"/>
    <geometry>
      <mesh filename="package://zeta_urdf_description/meshes/FL_1_Motor_1.stl" scale="0.001 0.001 0.001"/>
    </geometry>
  </collision>
</link>

<link name="FL_3_Motor_1">
  <inertial>
    <origin xyz="0.00023268298076506433 -0.0038812370107810246 -4.0692889374804864e-07" rpy="0 0 0"/>
    <mass value="0.09250068837166625"/>
    <inertia ixx="0.0001" ixy="0.000"  ixz="0.000"  
         iyy="0.0001" iyz="0.000"
         izz="0.0001"
/>
  </inertial>
  <visual>
    <origin xyz="-0.720473 0.44918 -0.242258" rpy="0 0 0"/>
    <geometry>
      <mesh filename="package://zeta_urdf_description/meshes/FL_3_Motor_1.stl" scale="0.001 0.001 0.001"/>
    </geometry>
    <material name="opaque252525"/>
  </visual>
  <collision>
    <origin xyz="-0.720473 0.44918 -0.242258" rpy="0 0 0"/>
    <geometry>
      <mesh filename="package://zeta_urdf_description/meshes/FL_3_Motor_1.stl" scale="0.001 0.001 0.001"/>
    </geometry>
  </collision>
</link>

<link name="BL_2_Motor_1">
  <inertial>
    <origin xyz="-0.009461781631035449 -0.015482968305633948 -0.00946214634669601" rpy="0 0 0"/>
    <mass value="0.09250068837133454"/>
    <inertia ixx="0.0001" ixy="0.000"  ixz="0.000"  
         iyy="0.0001" iyz="0.000"
         izz="0.0001"
/>
  </inertial>
  <visual>
    <origin xyz="-0.450623 0.364211 -0.190939" rpy="0 0 0"/>
    <geometry>
      <mesh filename="package://zeta_urdf_description/meshes/BL_2_Motor_1.stl" scale="0.001 0.001 0.001"/>
    </geometry>
    <material name="opaque252525"/>
  </visual>
  <collision>
    <origin xyz="-0.450623 0.364211 -0.190939" rpy="0 0 0"/>
    <geometry>
      <mesh filename="package://zeta_urdf_description/meshes/BL_2_Motor_1.stl" scale="0.001 0.001 0.001"/>
    </geometry>
  </collision>
</link>

<link name="FR_Foot_1">
  <inertial>
    <origin xyz="0.056448933720338434 0.015446958937245348 -0.056449484510780606" rpy="0 0 0"/>
    <mass value="0.05025436616494203"/>
    <inertia ixx="0.0001" ixy="0.000"  ixz="0.000"  
         iyy="0.0001" iyz="0.000"
         izz="0.0001"
/>
  </inertial>
  <visual>
    <origin xyz="-0.667176 0.593799 -0.136492" rpy="0 0 0"/>
    <geometry>
      <mesh filename="package://zeta_urdf_description/meshes/FR_Foot_1.stl" scale="0.001 0.001 0.001"/>
    </geometry>
    <material name="opaque252525"/>
  </visual>
  <collision>
    <origin xyz="-0.667176 0.593799 -0.136492" rpy="0 0 0"/>
    <geometry>
      <mesh filename="package://zeta_urdf_description/meshes/FR_Foot_1.stl" scale="0.001 0.001 0.001"/>
    </geometry>
  </collision>
</link>

<link name="BL_Foot_1">
  <inertial>
    <origin xyz="0.05644893372033977 -0.015447107956213624 -0.05644948451077919" rpy="0 0 0"/>
    <mass value="0.05025436616494222"/>
    <inertia ixx="0.0001" ixy="0.000"  ixz="0.000"  
         iyy="0.0001" iyz="0.000"
         izz="0.0001"
/>
  </inertial>
  <visual>
    <origin xyz="-0.396176 0.364961 -0.136492" rpy="0 0 0"/>
    <geometry>
      <mesh filename="package://zeta_urdf_description/meshes/BL_Foot_1.stl" scale="0.001 0.001 0.001"/>
    </geometry>
    <material name="opaque252525"/>
  </visual>
  <collision>
    <origin xyz="-0.396176 0.364961 -0.136492" rpy="0 0 0"/>
    <geometry>
      <mesh filename="package://zeta_urdf_description/meshes/BL_Foot_1.stl" scale="0.001 0.001 0.001"/>
    </geometry>
  </collision>
</link>

<link name="FR_1_Motor_1">
  <inertial>
    <origin xyz="0.0027442419608072477 0.0002328192868662482 0.0027450287384346295" rpy="0 0 0"/>
    <mass value="0.09250068837172258"/>
    <inertia ixx="0.0001" ixy="0.000"  ixz="0.000"  
         iyy="0.0001" iyz="0.000"
         izz="0.0001"
/>
  </inertial>
  <visual>
    <origin xyz="-0.673893 0.579299 -0.143209" rpy="0 0 0"/>
    <geometry>
      <mesh filename="package://zeta_urdf_description/meshes/FR_1_Motor_1.stl" scale="0.001 0.001 0.001"/>
    </geometry>
    <material name="opaque252525"/>
  </visual>
  <collision>
    <origin xyz="-0.673893 0.579299 -0.143209" rpy="0 0 0"/>
    <geometry>
      <mesh filename="package://zeta_urdf_description/meshes/FR_1_Motor_1.stl" scale="0.001 0.001 0.001"/>
    </geometry>
  </collision>
</link>

<link name="BR_Foot_1">
  <inertial>
    <origin xyz="0.0564489337203386 0.015446958937248012 -0.056449484510775555" rpy="0 0 0"/>
    <mass value="0.05025436616494205"/>
    <inertia ixx="0.0001" ixy="0.000"  ixz="0.000"  
         iyy="0.0001" iyz="0.000"
         izz="0.0001"
/>
  </inertial>
  <visual>
    <origin xyz="-0.396176 0.593799 -0.136492" rpy="0 0 0"/>
    <geometry>
      <mesh filename="package://zeta_urdf_description/meshes/BR_Foot_1.stl" scale="0.001 0.001 0.001"/>
    </geometry>
    <material name="opaque252525"/>
  </visual>
  <collision>
    <origin xyz="-0.396176 0.593799 -0.136492" rpy="0 0 0"/>
    <geometry>
      <mesh filename="package://zeta_urdf_description/meshes/BR_Foot_1.stl" scale="0.001 0.001 0.001"/>
    </geometry>
  </collision>
</link>

<link name="BL_1_Motor_1">
  <inertial>
    <origin xyz="0.002744241959910687 -0.0002329683056337406 0.0027450287390365924" rpy="0 0 0"/>
    <mass value="0.09250068837133459"/>
    <inertia ixx="0.0001" ixy="0.000"  ixz="0.000"  
         iyy="0.0001" iyz="0.000"
         izz="0.0001"
/>
  </inertial>
  <visual>
    <origin xyz="-0.402893 0.379461 -0.143209" rpy="0 0 0"/>
    <geometry>
      <mesh filename="package://zeta_urdf_description/meshes/BL_1_Motor_1.stl" scale="0.001 0.001 0.001"/>
    </geometry>
    <material name="opaque252525"/>
  </visual>
  <collision>
    <origin xyz="-0.402893 0.379461 -0.143209" rpy="0 0 0"/>
    <geometry>
      <mesh filename="package://zeta_urdf_description/meshes/BL_1_Motor_1.stl" scale="0.001 0.001 0.001"/>
    </geometry>
  </collision>
</link>

<link name="FR_Dual_Motor_Mount_1">
  <inertial>
    <origin xyz="-0.017856322959954762 -2.235312746012852e-08 -0.017858804520422294" rpy="0 0 0"/>
    <mass value="0.023417593270725956"/>
    <inertia ixx="0.0001" ixy="0.000"  ixz="0.000"  
         iyy="0.0001" iyz="0.000"
         izz="0.0001"
/>
  </inertial>
  <visual>
    <origin xyz="-0.71243 0.579299 -0.181747" rpy="0 0 0"/>
    <geometry>
      <mesh filename="package://zeta_urdf_description/meshes/FR_Dual_Motor_Mount_1.stl" scale="0.001 0.001 0.001"/>
    </geometry>
    <material name="opaque252525"/>
  </visual>
  <collision>
    <origin xyz="-0.71243 0.579299 -0.181747" rpy="0 0 0"/>
    <geometry>
      <mesh filename="package://zeta_urdf_description/meshes/FR_Dual_Motor_Mount_1.stl" scale="0.001 0.001 0.001"/>
    </geometry>
  </collision>
</link>

<link name="FR_2_Motor_1">
  <inertial>
    <origin xyz="-0.009461781630290433 0.015482819286866012 -0.009462146347450323" rpy="0 0 0"/>
    <mass value="0.09250068837172218"/>
    <inertia ixx="0.0001" ixy="0.000"  ixz="0.000"  
         iyy="0.0001" iyz="0.000"
         izz="0.0001"
/>
  </inertial>
  <visual>
    <origin xyz="-0.721623 0.594549 -0.190939" rpy="0 0 0"/>
    <geometry>
      <mesh filename="package://zeta_urdf_description/meshes/FR_2_Motor_1.stl" scale="0.001 0.001 0.001"/>
    </geometry>
    <material name="opaque252525"/>
  </visual>
  <collision>
    <origin xyz="-0.721623 0.594549 -0.190939" rpy="0 0 0"/>
    <geometry>
      <mesh filename="package://zeta_urdf_description/meshes/FR_2_Motor_1.stl" scale="0.001 0.001 0.001"/>
    </geometry>
  </collision>
</link>

<link name="BR_1_Motor_1">
  <inertial>
    <origin xyz="0.0027442419611180546 0.0002328192868688017 0.002745028738439542" rpy="0 0 0"/>
    <mass value="0.09250068837172253"/>
    <inertia ixx="0.0001" ixy="0.000"  ixz="0.000"  
         iyy="0.0001" iyz="0.000"
         izz="0.0001"
/>
  </inertial>
  <visual>
    <origin xyz="-0.402893 0.579299 -0.143209" rpy="0 0 0"/>
    <geometry>
      <mesh filename="package://zeta_urdf_description/meshes/BR_1_Motor_1.stl" scale="0.001 0.001 0.001"/>
    </geometry>
    <material name="opaque252525"/>
  </visual>
  <collision>
    <origin xyz="-0.402893 0.579299 -0.143209" rpy="0 0 0"/>
    <geometry>
      <mesh filename="package://zeta_urdf_description/meshes/BR_1_Motor_1.stl" scale="0.001 0.001 0.001"/>
    </geometry>
  </collision>
</link>

<link name="BR_Dual_Motor_Mount_1">
  <inertial>
    <origin xyz="-0.01803076983473978 -2.235312068776807e-08 -0.01803155880432622" rpy="0 0 0"/>
    <mass value="0.02330043804691809"/>
    <inertia ixx="0.0001" ixy="0.000"  ixz="0.000"  
         iyy="0.0001" iyz="0.000"
         izz="0.0001"
/>
  </inertial>
  <visual>
    <origin xyz="-0.44143 0.579299 -0.181747" rpy="0 0 0"/>
    <geometry>
      <mesh filename="package://zeta_urdf_description/meshes/BR_Dual_Motor_Mount_1.stl" scale="0.001 0.001 0.001"/>
    </geometry>
    <material name="opaque252525"/>
  </visual>
  <collision>
    <origin xyz="-0.44143 0.579299 -0.181747" rpy="0 0 0"/>
    <geometry>
      <mesh filename="package://zeta_urdf_description/meshes/BR_Dual_Motor_Mount_1.stl" scale="0.001 0.001 0.001"/>
    </geometry>
  </collision>
</link>

<link name="BR_2_Motor_1">
  <inertial>
    <origin xyz="-0.009461781629981347 0.0154828192868679 -0.00946214634744924" rpy="0 0 0"/>
    <mass value="0.09250068837172205"/>
    <inertia ixx="0.0001" ixy="0.000"  ixz="0.000"  
         iyy="0.0001" iyz="0.000"
         izz="0.0001"
/>
  </inertial>
  <visual>
    <origin xyz="-0.450623 0.594549 -0.190939" rpy="0 0 0"/>
    <geometry>
      <mesh filename="package://zeta_urdf_description/meshes/BR_2_Motor_1.stl" scale="0.001 0.001 0.001"/>
    </geometry>
    <material name="opaque252525"/>
  </visual>
  <collision>
    <origin xyz="-0.450623 0.594549 -0.190939" rpy="0 0 0"/>
    <geometry>
      <mesh filename="package://zeta_urdf_description/meshes/BR_2_Motor_1.stl" scale="0.001 0.001 0.001"/>
    </geometry>
  </collision>
</link>

<joint name="FL_1" type="continuous">
  <origin xyz="-0.006717 0.0145 -0.006717" rpy="0 0 0"/>
  <parent link="FL_1_Motor_1"/>
  <child link="FL_Foot_1"/>
  <axis xyz="-0.0 -1.0 -0.0"/>
</joint>

<joint name="FL_M_2" type="fixed">
  <origin xyz="-0.009193 -0.01525 -0.009192" rpy="0 0 0"/>
  <parent link="FL_2_Motor_1"/>
  <child link="FL_Dual_Motor_Mount_1"/>
</joint>

<joint name="FL_3" type="continuous">
  <origin xyz="-0.0145 0.0095 0.0" rpy="0 0 0"/>
  <parent link="FL_3_Motor_1"/>
  <child link="FL_Top_Bracket_1"/>
  <axis xyz="1.0 -0.0 -0.0"/>
</joint>

<joint name="FR_3" type="continuous">
  <origin xyz="-0.0145 -0.0095 0.0" rpy="0 0 0"/>
  <parent link="FR_3_Motor_1"/>
  <child link="FR_Top_Bracket_1"/>
  <axis xyz="-1.0 0.0 0.0"/>
</joint>

<joint name="FR_M_3" type="fixed">
  <origin xyz="0.720473 -0.50958 0.242258" rpy="0 0 0"/>
  <parent link="base_link"/>
  <child link="FR_3_Motor_1"/>
</joint>

<joint name="R_Pipe" type="fixed">
  <origin xyz="0.469873 -0.499765 0.242258" rpy="0 0 0"/>
  <parent link="base_link"/>
  <child link="Pipe_R_1"/>
</joint>

<joint name="L_Pipe" type="fixed">
  <origin xyz="0.469873 -0.458995 0.242258" rpy="0 0 0"/>
  <parent link="base_link"/>
  <child link="Pipe_L_1"/>
</joint>

<joint name="BR_M_3" type="fixed">
  <origin xyz="0.449473 -0.50958 0.242258" rpy="0 0 0"/>
  <parent link="base_link"/>
  <child link="BR_3_Motor_1"/>
</joint>

<joint name="BL_M_3" type="fixed">
  <origin xyz="0.449473 -0.44918 0.242258" rpy="0 0 0"/>
  <parent link="base_link"/>
  <child link="BL_3_Motor_1"/>
</joint>

<joint name="BR_3" type="continuous">
  <origin xyz="-0.0145 -0.0095 0.0" rpy="0 0 0"/>
  <parent link="BR_3_Motor_1"/>
  <child link="BR_Top_Bracket_1"/>
  <axis xyz="-1.0 0.0 0.0"/>
</joint>

<joint name="BL_M_2" type="fixed">
  <origin xyz="-0.009193 -0.01525 -0.009192" rpy="0 0 0"/>
  <parent link="BL_2_Motor_1"/>
  <child link="BL_Dual_Motor_Mount_1"/>
</joint>

<joint name="BL_3" type="continuous">
  <origin xyz="-0.0145 0.0095 0.0" rpy="0 0 0"/>
  <parent link="BL_3_Motor_1"/>
  <child link="BL_Top_Bracket_1"/>
  <axis xyz="1.0 -0.0 -0.0"/>
</joint>

<joint name="FL_2" type="continuous">
  <origin xyz="0.01565 0.075469 -0.051319" rpy="0 0 0"/>
  <parent link="FL_Top_Bracket_1"/>
  <child link="FL_2_Motor_1"/>
  <axis xyz="0.0 -1.0 0.0"/>
</joint>

<joint name="FL_M_1" type="fixed">
  <origin xyz="-0.038537 0.0 -0.038538" rpy="0 0 0"/>
  <parent link="FL_Dual_Motor_Mount_1"/>
  <child link="FL_1_Motor_1"/>
</joint>

<joint name="FL_M_3" type="fixed">
  <origin xyz="0.720473 -0.44918 0.242258" rpy="0 0 0"/>
  <parent link="base_link"/>
  <child link="FL_3_Motor_1"/>
</joint>

<joint name="BL_2" type="continuous">
  <origin xyz="0.01565 0.075469 -0.051319" rpy="0 0 0"/>
  <parent link="BL_Top_Bracket_1"/>
  <child link="BL_2_Motor_1"/>
  <axis xyz="-0.0 -1.0 -0.0"/>
</joint>

<joint name="FR_1" type="continuous">
  <origin xyz="-0.006717 -0.0145 -0.006717" rpy="0 0 0"/>
  <parent link="FR_1_Motor_1"/>
  <child link="FR_Foot_1"/>
  <axis xyz="-0.0 -1.0 0.0"/>
</joint>

<joint name="BL_1" type="continuous">
  <origin xyz="-0.006717 0.0145 -0.006717" rpy="0 0 0"/>
  <parent link="BL_1_Motor_1"/>
  <child link="BL_Foot_1"/>
  <axis xyz="-0.0 -1.0 -0.0"/>
</joint>

<joint name="FR_M_1" type="fixed">
  <origin xyz="-0.038537 0.0 -0.038538" rpy="0 0 0"/>
  <parent link="FR_Dual_Motor_Mount_1"/>
  <child link="FR_1_Motor_1"/>
</joint>

<joint name="BR_1" type="continuous">
  <origin xyz="-0.006717 -0.0145 -0.006717" rpy="0 0 0"/>
  <parent link="BR_1_Motor_1"/>
  <child link="BR_Foot_1"/>
  <axis xyz="-0.0 -1.0 0.0"/>
</joint>

<joint name="BL_M_1" type="fixed">
  <origin xyz="-0.038537 0.0 -0.038538" rpy="0 0 0"/>
  <parent link="BL_Dual_Motor_Mount_1"/>
  <child link="BL_1_Motor_1"/>
</joint>

<joint name="FR_M_2" type="fixed">
  <origin xyz="-0.009193 0.01525 -0.009192" rpy="0 0 0"/>
  <parent link="FR_2_Motor_1"/>
  <child link="FR_Dual_Motor_Mount_1"/>
</joint>

<joint name="FR_2" type="continuous">
  <origin xyz="0.01565 -0.075469 -0.051319" rpy="0 0 0"/>
  <parent link="FR_Top_Bracket_1"/>
  <child link="FR_2_Motor_1"/>
  <axis xyz="-0.0 -1.0 0.0"/>
</joint>

<joint name="BR_M_1" type="fixed">
  <origin xyz="-0.038537 0.0 -0.038538" rpy="0 0 0"/>
  <parent link="BR_Dual_Motor_Mount_1"/>
  <child link="BR_1_Motor_1"/>
</joint>

<joint name="BR_M_2" type="fixed">
  <origin xyz="-0.009193 0.01525 -0.009192" rpy="0 0 0"/>
  <parent link="BR_2_Motor_1"/>
  <child link="BR_Dual_Motor_Mount_1"/>
</joint>

<joint name="BR_2" type="continuous">
  <origin xyz="0.01565 -0.075469 -0.051319" rpy="0 0 0"/>
  <parent link="BR_Top_Bracket_1"/>
  <child link="BR_2_Motor_1"/>
  <axis xyz="-0.0 -1.0 0.0"/>
</joint>

</robot>
